<?xml version="1.0"?>
<robot xmlns:xacro="http://www.ros.org/wiki/xacro" >

    <xacro:include filename="inertial_macros.xacro" />
    
    <material name="white">
        <color rgba="1 1 1 1" />
    </material>

    <material name="orange">
        <color rgba="1 0.3 0.1 1"/>
    </material>

    <material name="blue">
        <color rgba="0.2 0.2 1 1"/>
    </material>

    <material name="black">
        <color rgba="0 0 0 1"/>
    </material>

    <material name="red">
        <color rgba="1 0 0 1"/>
    </material>

    <!-- BASE LINK -->

    <link name="base_link">

    </link>


    <!-- CHASSIS LINK -->

    <joint name="chassis_joint" type="fixed">
        <parent link="base_link"/>
        <child link="chassis"/>
        <origin xyz="-0.125 0 0"/>
    </joint>

    <link name="chassis">
        <visual>
            <origin xyz="0.185 0 0.07"/>
            <geometry>
                <box size="0.370 0.230 0.140"/>
            </geometry>
            <material name="white"/>
        </visual>

        <collision>
            <origin xyz="0.185 0 0.07"/>
            <geometry>
                <box size="0.370 0.230 0.140"/>
            </geometry>
        </collision>

        <xacro:inertial_box mass = "1.4" x = "0.370" y = "0.230" z = "0.140">
            <origin xyz="0.185 0 0.07" rpy = "0 0 0"/>
        </xacro:inertial_box> 
    </link>
    
    <gazebo reference="chassis">
        <material>Gazebo/White</material>
    </gazebo>
    
    <!-- LEFT WHEEL LINK -->

    <joint name="left_wheel_joint" type="continuous">
        <parent link="base_link"/>
        <child link="left_wheel"/>
        <origin xyz="0 0.120 0" rpy="-${pi/2} 0 0" />
        <axis xyz="0 0 1"/>
    </joint>

    <link name="left_wheel">
        <visual>
            <geometry>
                <cylinder radius="0.033" length="0.027"/>
            </geometry>
            <material name="blue"/>
        </visual>
        <collision>
            <geometry>
                <cylinder radius="0.033" length="0.027"/>
            </geometry>
        </collision>
        <xacro:inertial_cylinder mass = "0.035" length = "0.027" radius = "0.033">
            <origin xyz="0 0 0" rpy = "0 0 0"/>
        </xacro:inertial_cylinder>
    </link>

    <gazebo reference="left_wheel">
        <material>Gazebo/Blue</material>
    </gazebo>

    <!-- RIGHT WHEEL LINK -->

    <joint name="right_wheel_joint" type="continuous">
        <parent link="base_link"/>
        <child link="right_wheel"/>
        <origin xyz="0 -0.120 0" rpy="${pi/2} 0 0" />
        <axis xyz="0 0 -1"/>
    </joint>

    <link name="right_wheel">
        <visual>
            <geometry>
                <cylinder radius="0.033" length="0.027"/>
            </geometry>
            <material name="blue"/>
        </visual>
        <collision>
            <geometry>
                <cylinder radius="0.033" length="0.027"/>
            </geometry>
        </collision>
        <xacro:inertial_cylinder mass = "0.035" length = "0.027" radius = "0.033">
            <origin xyz="0 0 0" rpy = "0 0 0"/>
        </xacro:inertial_cylinder>
    </link>
    
    <gazebo reference="right_wheel">
        <material>Gazebo/Blue</material>
    </gazebo>

    <!-- CASTOR WHEEL LINK -->
    <joint name="castor_wheel_joint" type="fixed">
        <parent link="chassis"/>
        <child link="castor_wheel"/>
        <origin xyz="0.270 0 0"/>
    </joint>

    <link name="castor_wheel">
        <visual>
            <geometry>
                <sphere radius="0.033" />
            </geometry>
            <material name="black"/>
        </visual>
        <collision>
            <geometry>
                <sphere radius="0.033" />
            </geometry>
        </collision>
        <xacro:inertial_sphere mass = "0.030" radius = "0.033">
            <origin xyz="0 0 0" rpy = "0 0 0"/>
        </xacro:inertial_sphere>
    </link>
    
    <gazebo reference="castor_wheel">
        <material>Gazebo/Black</material>
        <mu1 value="0.00001"/>
        <mu2 value="0.00001"/>
    </gazebo>

</robot>